<?xml version="1.0" encoding="utf-8"?>
<!-- This URDF was automatically created by SolidWorks to URDF Exporter! Originally created by Stephen Brawner (brawner@gmail.com) 
     Commit Version: 1.6.0-4-g7f85cfe  Build Version: 1.6.7995.38578
     For more information, please see http://wiki.ros.org/sw_urdf_exporter -->
<robot
  name="MECNUMROBOT">
  <link
    name="base_link">
    <inertial>
      <origin
        xyz="0.0004486 0.00083903 -0.022532"
        rpy="0 0 0" />
      <mass
        value="3.558" />
      <inertia
        ixx="0.0092111"
        ixy="-1.6996E-05"
        ixz="4.6457E-06"
        iyy="0.019941"
        iyz="-1.5765E-07"
        izz="0.027091" />
    </inertial>
    <visual>
      <origin
        xyz="0 0 0"
        rpy="0 0 0" />
      <geometry>
        <mesh
          filename="package://MECNUMROBOT/meshes/base_link.STL" />
      </geometry>
      <material
        name="">
        <color
          rgba="1 0.5 0 1" />
      </material>
    </visual>
    <collision>
      <origin
        xyz="0 0 0"
        rpy="0 0 0" />
      <geometry>
        <mesh
          filename="package://MECNUMROBOT/meshes/base_link.STL" />
      </geometry>
    </collision>
  </link>
  <link
    name="rear_right_wheel">
    <inertial>
      <origin
        xyz="-2.2835E-06 3.7979E-07 0.00071836"
        rpy="0 0 0" />
      <mass
        value="1.0289" />
      <inertia
        ixx="0.00017755"
        ixy="1.2488E-08"
        ixz="-2.5268E-09"
        iyy="0.00017761"
        iyz="-1.3435E-08"
        izz="0.00022365" />
    </inertial>
    <visual>
      <origin
        xyz="0 0 0"
        rpy="0 0 0" />
      <geometry>
        <mesh
          filename="package://MECNUMROBOT/meshes/rear_right_wheel.STL" />
      </geometry>
      <material
        name="">
        <color
          rgba="1 1 0 1" />
      </material>
    </visual>
    <collision>
      <origin
        xyz="0 0 0"
        rpy="0 0 0" />
      <geometry>
        <mesh
          filename="package://MECNUMROBOT/meshes/rear_right_wheel.STL" />
      </geometry>
    </collision>
  </link>
  <joint
    name="rear_right_wheel_wheel"
    type="continuous">
    <origin
      xyz="-0.1265 -0.12365 -0.03885"
      rpy="-1.5708 0 -3.1416" />
    <parent
      link="base_link" />
    <child
      link="rear_right_wheel" />
    <axis
      xyz="0 0 1" />
  </joint>
  <link
    name="front_right_wheel">
    <inertial>
      <origin
        xyz="1.4264E-06 1.6554E-06 0.00077886"
        rpy="0 0 0" />
      <mass
        value="1.0289" />
      <inertia
        ixx="0.00017758"
        ixy="-3.4031E-08"
        ixz="1.0423E-08"
        iyy="0.00017757"
        iyz="-8.8206E-09"
        izz="0.00022365" />
    </inertial>
    <visual>
      <origin
        xyz="0 0 0"
        rpy="0 0 0" />
      <geometry>
        <mesh
          filename="package://MECNUMROBOT/meshes/front_right_wheel.STL" />
      </geometry>
      <material
        name="">
        <color
          rgba="1 1 0 1" />
      </material>
    </visual>
    <collision>
      <origin
        xyz="0 0 0"
        rpy="0 0 0" />
      <geometry>
        <mesh
          filename="package://MECNUMROBOT/meshes/front_right_wheel.STL" />
      </geometry>
    </collision>
  </link>
  <joint
    name="front_right_wheel_joint"
    type="continuous">
    <origin
      xyz="0.1265 -0.12365 -0.03885"
      rpy="-1.5708 0 -3.1416" />
    <parent
      link="base_link" />
    <child
      link="front_right_wheel" />
    <axis
      xyz="0 0 1" />
  </joint>
  <link
    name="front_left_wheel">
    <inertial>
      <origin
        xyz="1.405E-06 -1.8181E-06 -0.00071849"
        rpy="0 0 0" />
      <mass
        value="1.0289" />
      <inertia
        ixx="0.00017759"
        ixy="3.2579E-08"
        ixz="1.1318E-08"
        iyy="0.00017757"
        iyz="7.7617E-09"
        izz="0.00022365" />
    </inertial>
    <visual>
      <origin
        xyz="0 0 0"
        rpy="0 0 0" />
      <geometry>
        <mesh
          filename="package://MECNUMROBOT/meshes/front_left_wheel.STL" />
      </geometry>
      <material
        name="">
        <color
          rgba="1 1 0 1" />
      </material>
    </visual>
    <collision>
      <origin
        xyz="0 0 0"
        rpy="0 0 0" />
      <geometry>
        <mesh
          filename="package://MECNUMROBOT/meshes/front_left_wheel.STL" />
      </geometry>
    </collision>
  </link>
  <joint
    name="front_left_wheel_joint"
    type="continuous">
    <origin
      xyz="0.1265 0.12365 -0.03885"
      rpy="-1.5708 0 -3.1416" />
    <parent
      link="base_link" />
    <child
      link="front_left_wheel" />
    <axis
      xyz="0 0 1" />
  </joint>
  <link
    name="rear_left_wheel">
    <inertial>
      <origin
        xyz="-1.5059E-06 1.5491E-06 -0.00077889"
        rpy="0 0 0" />
      <mass
        value="1.0289" />
      <inertia
        ixx="0.00017758"
        ixy="3.4608E-08"
        ixz="9.6664E-09"
        iyy="0.00017758"
        iyz="9.6256E-09"
        izz="0.00022365" />
    </inertial>
    <visual>
      <origin
        xyz="0 0 0"
        rpy="0 0 0" />
      <geometry>
        <mesh
          filename="package://MECNUMROBOT/meshes/rear_left_wheel.STL" />
      </geometry>
      <material
        name="">
        <color
          rgba="1 1 0 1" />
      </material>
    </visual>
    <collision>
      <origin
        xyz="0 0 0"
        rpy="0 0 0" />
      <geometry>
        <mesh
          filename="package://MECNUMROBOT/meshes/rear_left_wheel.STL" />
      </geometry>
    </collision>
  </link>
  <joint
    name="rear_left_wheel_joint"
    type="continuous">
    <origin
      xyz="-0.1265 0.12365 -0.03885"
      rpy="-1.5708 0 -3.1416" />
    <parent
      link="base_link" />
    <child
      link="rear_left_wheel" />
    <axis
      xyz="0 0 1" />
  </joint>
  <link
    name="lidar">
    <inertial>
      <origin
        xyz="0.0082941 1.1168E-14 -0.0085489"
        rpy="0 0 0" />
      <mass
        value="0.1467" />
      <inertia
        ixx="6.2272E-05"
        ixy="-6.6101E-18"
        ixz="1.8866E-05"
        iyy="0.00010967"
        iyz="2.1232E-16"
        izz="0.00012568" />
    </inertial>
    <visual>
      <origin
        xyz="0 0 0"
        rpy="0 0 0" />
      <geometry>
        <mesh
          filename="package://MECNUMROBOT/meshes/lidar.STL" />
      </geometry>
      <material
        name="">
        <color
          rgba="0 0 0 1" />
      </material>
    </visual>
    <collision>
      <origin
        xyz="0 0 0"
        rpy="0 0 0" />
      <geometry>
        <mesh
          filename="package://MECNUMROBOT/meshes/lidar.STL" />
      </geometry>
    </collision>
  </link>
  <joint
    name="lidar_joint"
    type="fixed">
    <origin
      xyz="0 0 0.04625"
      rpy="0 0 0" />
    <parent
      link="base_link" />
    <child
      link="lidar" />
    <axis
      xyz="0 0 0" />
  </joint>
  <link
    name="camera">
    <inertial>
      <origin
        xyz="-0.0093756 -0.011232 0.00073677"
        rpy="0 0 0" />
      <mass
        value="0.0036832" />
      <inertia
        ixx="5.5289E-07"
        ixy="-3.5562E-08"
        ixz="3.9449E-09"
        iyy="1.8082E-07"
        iyz="9.4699E-09"
        izz="4.2671E-07" />
    </inertial>
    <visual>
      <origin
        xyz="0 0 0"
        rpy="0 0 0" />
      <geometry>
        <mesh
          filename="package://MECNUMROBOT/meshes/camera.STL" />
      </geometry>
      <material
        name="">
        <color
          rgba="1 1 1 1" />
      </material>
    </visual>
    <collision>
      <origin
        xyz="0 0 0"
        rpy="0 0 0" />
      <geometry>
        <mesh
          filename="package://MECNUMROBOT/meshes/camera.STL" />
      </geometry>
    </collision>
  </link>
  <joint
    name="camera_joint"
    type="fixed">
    <origin
      xyz="0.17435 0 0.02045"
      rpy="0 0 0" />
    <parent
      link="base_link" />
    <child
      link="camera" />
    <axis
      xyz="0 0 0" />
  </joint>
  <link
    name="imu">
    <inertial>
      <origin
        xyz="-3.9295E-05 -0.0014664 -0.00041921"
        rpy="0 0 0" />
      <mass
        value="0.00077106" />
      <inertia
        ixx="1.3877E-08"
        ixy="7.6765E-10"
        ixz="-7.5369E-15"
        iyy="2.6926E-08"
        iyz="-2.4674E-15"
        izz="3.9518E-08" />
    </inertial>
    <visual>
      <origin
        xyz="0 0 0"
        rpy="0 0 0" />
      <geometry>
        <mesh
          filename="package://MECNUMROBOT/meshes/imu.STL" />
      </geometry>
      <material
        name="">
        <color
          rgba="0 0 1 1" />
      </material>
    </visual>
    <collision>
      <origin
        xyz="0 0 0"
        rpy="0 0 0" />
      <geometry>
        <mesh
          filename="package://MECNUMROBOT/meshes/imu.STL" />
      </geometry>
    </collision>
  </link>
  <joint
    name="imu_joint"
    type="fixed">
    <origin
      xyz="0.026514 -0.050753 0.00761"
      rpy="0 0 0" />
    <parent
      link="base_link" />
    <child
      link="imu" />
    <axis
      xyz="0 0 0" />
  </joint>
</robot>